Performing speed test no.5
Traceback (most recent call last):
  File "speedtest.py", line 27, in get_speedtest_json
    _dict = json.loads(_json)
  File "C:\Users\Jenny\AppData\Local\Programs\Python\Python38-32\lib\json\__init__.py", line 357, in loads
    return _default_decoder.decode(s)
  File "C:\Users\Jenny\AppData\Local\Programs\Python\Python38-32\lib\json\decoder.py", line 340, in decode
    raise JSONDecodeError("Extra data", s, end)
json.decoder.JSONDecodeError: Extra data: line 2 column 1 (char 111)

During handling of the above exception, another exception occurred:

Traceback (most recent call last):
  File "speedtest.py", line 159, in <module>
    _dict = collect_speeds(iters, mins)
  File "speedtest.py", line 68, in collect_speeds
    _dict = get_speedtest_json()
  File "speedtest.py", line 29, in get_speedtest_json
    except (JSONDecodeError, UnboundLocalError, ValueError):
NameError: name 'JSONDecodeError' is not defined


